Workbook

Sheet 1. Business Case
A1: Barefoot Addo Elephant Lodge — Own-Network Business Case
A2: Why build a private carrier-grade network instead of continuing to rent one, month after month, forever.
A4: Prepared for: Barefoot Addo Elephant Lodge (Pty) Ltd owners (Port Elizabeth)
A5: Prepared by: Gerhard Smit, CTTX Services (Pty) Ltd
A6: Date: 26 September 2026
A8: The Simple Version
A9: Right now the lodge pays a monthly bill to Herotel forever, for equipment it will never own, on a network it does not control. This proposal is the alternative: pay once to build a private network on your own engineered mast, then pay a much smaller monthly fee for the carrier link that feeds it. The network is built to run for 10 years, and CTTX supports it for that whole period.
A13: Headline Numbers
A14: One-time build cost (infrastructure, owned by the lodge) | E14: ='2. Network Build Investment'!C6
A15: Current Herotel monthly bill (connectivity + rented Wi-Fi equipment) | E15: ='3. Monthly Cost Comparison'!C11
A16: New monthly bill once built (Vodacom link + CTTX monitoring - recommended) | E16: ='3. Monthly Cost Comparison'!C26
A17: Monthly saving once built | E17: =E15-E16
A18: Time to pay back the build cost | E18: ='4. 5-Year Cash Flow'!B29
A19: Total saved over 5 years vs staying with Herotel | E19: ='4. 5-Year Cash Flow'!I31
A20: 5-Year Return on Investment | E20: ='4. 5-Year Cash Flow'!I32
A22: Why This Makes Sense Over 10 Years
A23: 1. The lodge currently pays for connectivity AND for the right to use someone else's Wi-Fi equipment, every month, indefinitely. Nothing is ever owned.
A24: 2. The existing backhaul radios are mounted on a leaning gum pole - not an engineered structure. That is a physical failure risk, separate from the cost problem.
A25: 3. Building a private network converts a forever-rising monthly rental into a one-time build cost plus a much smaller ongoing carrier fee for just the connectivity - the Wi-Fi equipment, the mast, and the solar power all become the lodge's own asset.
A26: 4. CTTX designs, builds, and supports this network for an expected 10-year working life - see tab 5 for what that support includes and excludes.
A27: 5. See tab 4 for the year-by-year numbers: the build cost is recovered from the monthly saving within the payback period shown above, and every month after that is money the lodge keeps instead of sending to a telecoms reseller.
A29: Full cost detail: tab 2 (build cost), tab 3 (monthly comparison), tab 4 (5-year cash flow), tab 5 (assumptions - read this before trusting any number on this page).

Sheet 2. Network Build Investment
A1: Network Build Investment
A2: Complete private wireless network - design, hardware, mast, cabinet, solar power system, installation, commissioning, and handover.
A4: Complete Network Build (Excl. VAT) | C4: 308695.65
A5: VAT (15%) | C5: =C4*0.15
A6: TOTAL BUILD INVESTMENT (Incl. VAT) | C6: =C4+C5
A8: Complete Scope of Supply
A9: Everything below is included in the build investment above. No per-item pricing is shown - this is the full scope of what gets installed, not a costed bill of materials.
A11: Item | D11: Qty
A12: Wireless Network Equipment
A13: Cambium ePMP 4500L 5GHz Base Station Access Point | D13: 2
A14: ePMP Sector Antenna, 5GHz, 90/120 degree | D14: 2
A15: Cambium ePMP Force 4525L Subscriber Module, 25dBi | D15: 28
A16: DuxNet Wi-Fi 6 Indoor Ceiling Access Point | D16: 28
A17: DuxNet Outdoor Dual-Band Wi-Fi 6 Access Point | D17: 2
A18: DuxNet 8-Port Gigabit PoE+ L2 Cloud Switch | D18: 4
A20: Mast & Foundation (Civil Works)
A21: 9m Galvanized Steel Lattice Mast | D21: 1
A22: Ready-mix concrete for foundation plinth | D22: As required
A23: Building sand | D23: As required
A24: Stone / grit aggregate (19mm) | D24: As required
A25: Reinforcing steel (rebar) for foundation | D25: As required
A26: Foundation shuttering / formwork | D26: As required
A27: Holding-down bolts (cast into plinth) | D27: Set
A28: Mast mounting brackets, U-bolts and clamps | D28: Set
A30: Power System (Solar & Battery)
A31: Outdoor equipment cabinet (weatherproof, IP-rated) | D31: 1
A32: MPPT solar charge controller | D32: 1
A33: Lithium battery bank and switchgear | D33: 1
A34: Canadian Solar 680W monocrystalline panel | D34: 4
A35: Solar panel mounting frame and rails | D35: Set
A36: Grid/solar inverter | D36: 1
A37: Solar combiner box | D37: 1
A38: DC and AC circuit breakers / isolators | D38: Set
A39: MC4 solar connectors | D39: Set
A41: Cabling & Conduit
A42: Outdoor-rated shielded Ethernet cable (Cat6A) | D42: As required
A43: LMR-400 low-loss antenna feeder cable | D43: As required
A44: Armored power cable | D44: As required
A45: Solar DC cable | D45: As required
A46: PVC conduit / cable trays | D46: As required
...

Sheet 3. Monthly Cost Comparison
A1: Monthly Cost — Current (Herotel) vs Proposed (CTTX)
A2: Herotel figures from Tax Invoice #8313058, dated 31 Aug 2026. CTTX/Vodacom figures are the confidential-cost-protected client price from the CTTX Vodacom Reseller Pricing Master (Notion, updated 15 June 2026) - never the underlying CTTX cost.
A4: Current: Herotel Business (what the lodge pays today)
A5: Item | B5: Excl. VAT | C5: Incl. VAT
A6: Business WTTB 100 Mbps Symmetrical | B6: 9999 | C6: 11498.85
A7: Static IP | B7: 180 | C7: 207
A8: Huawei Wi-Fi 6 AP 362 (Managed-lite, 9x 24-month term) | B8: 2061 | C8: 2370.15
A9: HB Managed Wi-Fi (Lite) 0-5 (x2) | B9: 298 | C9: 342.7
A10: Huawei Wi-Fi 6 AP 362 (Managed-lite, 14x 12-month term) | B10: 3206 | C10: 3686.9
A11: Herotel Monthly Total (current) | B11: =SUM(B6:B10) | C11: =SUM(C6:C10)
A13: Proposed: Vodacom Business Connect via CTTX (carrier connectivity only)
A14: Uncontended (1:1), Uncapped, Unshaped, No FUP, Symmetrical, Business SLA, LTE backup, Huawei router included, 1 static IP standard. 36-month contract. Subject to feasibility confirmation.
A15: Item | B15: Excl. VAT | C15: Incl. VAT
A16: Vodacom Business Connect 100 Mbps (Monthly Recurring Charge, 36-month term) | B16: 6281.74 | C16: 7224
A17: Once-off Connection Fee (NRC) - not monthly, shown for reference | B17: 3130 | C17: 3599
A18: Vodacom-Only Monthly Total | B18: =B16 | C18: =C16
A20: Optional Add-On: CTTX Managed Service Retainer (recommended)
A21: Remote monitoring (Cambium cnMaestro + Victron), proactive maintenance, quarterly on-site visits, battery/solar health checks, priority emergency support. CTTX does not deploy unmonitored infrastructure as a matter of policy.
A22: Item | B22: Excl. VAT | C22: Incl. VAT
A23: Managed Service Retainer (remote monitoring, maintenance, support) | B23: 1500 | C23: 1725
A25: Recommended Path: Vodacom + Managed Retainer
A26: Recommended Monthly Total (Vodacom + Retainer) | B26: =B16+B23 | C26: =C16+C23
A27: Monthly saving vs Herotel (recommended path, incl. VAT) | C27: =C11-C26
A28: Monthly saving vs Herotel (Vodacom-only, self-maintained, incl. VAT) | C28: =C11-C18

Sheet 4. 5-Year Cash Flow
A1: 5-Year Cash Flow — Build vs Keep Renting
A2: Year 0 = build year (deposit and construction). Years 1-5 are projected here deliberately, rather than compounding the escalation assumption out to a full decade. The network's engineered/expected working life is longer (see tab 5) and CTTX's support commitment runs 10 years - this cash flow is the near-term financial case, not a claim about how long the equipment lasts. All figures incl. VAT.
A4: Annual escalation rate (applied to both Herotel and Vodacom monthly fees) | B4: 0.08 | C4: <- editable assumption; see tab 5 for why 8% was used
A6: Year | B6: 0 | C6: 1 | D6: 2 | E6: 3 | F6: 4 | G6: 5
A7: Path A: Stay with Herotel (do nothing)
A8: Herotel monthly bill (escalated) | B8: ='3. Monthly Cost Comparison'!$C$11 | C8: =B8*(1+$B$4) | D8: =C8*(1+$B$4) | E8: =D8*(1+$B$4) | F8: =E8*(1+$B$4) | G8: =F8*(1+$B$4)
A9: Herotel annual cost | B9: =B8*12 | C9: =C8*12 | D9: =D8*12 | E9: =E8*12 | F9: =F8*12 | G9: =G8*12
A10: Herotel cumulative cost | B10: =B9 | C10: =B10+C9 | D10: =C10+D9 | E10: =D10+E9 | F10: =E10+F9 | G10: =F10+G9
A12: Path B: Build the CTTX private network (recommended - Vodacom + Managed Retainer)
A13: Build cost (one-time, Year 0 only) | B13: ='2. Network Build Investment'!$C$6 | C13: 0 | D13: 0 | E13: 0 | F13: 0 | G13: 0
A14: Vodacom once-off connection fee (Year 0 only) | B14: ='3. Monthly Cost Comparison'!$C$17 | C14: 0 | D14: 0 | E14: 0 | F14: 0 | G14: 0
A15: CTTX monthly recurring (Vodacom + Retainer, escalated) | B15: 0 | C15: ='3. Monthly Cost Comparison'!$C$26 | D15: =C15*(1+$B$4) | E15: =D15*(1+$B$4) | F15: =E15*(1+$B$4) | G15: =F15*(1+$B$4)
A16: CTTX annual recurring cost | B16: =B15*12 | C16: =C15*12 | D16: =D15*12 | E16: =E15*12 | F16: =F15*12 | G16: =G15*12
A17: CTTX cumulative cost | B17: =B13+B14+B16 | C17: =B17+C16 | D17: =C17+D16 | E17: =D17+E16 | F17: =E17+F16 | G17: =F17+G16
A19: Cumulative Savings (Path A minus Path B)
A20: Cumulative savings from building (negative = still paying off the build) | B20: =B10-B17 | C20: =C10-C17 | D20: =D10-D17 | E20: =E10-E17 | F20: =F10-F17 | G20: =G10-G17
A21: Return on Investment (cumulative savings vs. Herotel, as % of total upfront cash outlay) | B21: =B20/$B$17 | C21: =C20/$B$17 | D21: =D20/$B$17 | E21: =E20/$B$17 | F21: =F20/$B$17 | G21: =G20/$B$17
A23: Payback Calculation
A24: Last year cumulative savings still negative or zero (position in range) | B24: =MATCH(0,B20:G20,1)
A25: That year number | B25: =INDEX(B6:G6,B24)
A26: Cumulative savings at that year | B26: =INDEX(B20:G20,B24)
A27: Cumulative savings the following year | B27: =INDEX(B20:G20,B24+1)
A28: Payback point (years, decimal) | B28: =B25+(-B26)/(B27-B26)
A29: Payback point (plain English) | B29: =TEXT(INT(B28),"0")&" years, "&TEXT(ROUND((B28-INT(B28))*12,0),"0")&" months"
A31: Total 5-year saving vs Herotel (recommended path) | I31: =G20
A32: 5-Year ROI (total saving as % of total upfront cash outlay) | I32: =G21

Sheet 5. Assumptions & Scope
A1: Assumptions, Scope, and What's Not Yet Confirmed
A3: Financial Assumptions
A4: Assumption | B4: Value | C4: Basis
A5: Annual price escalation (Herotel and Vodacom) | B5: 8% p.a. | C5: Not confirmed by either party - a typical CPI-linked telecom escalation in South Africa. Editable on tab 4; change it and every formula recalculates.
A6: VAT rate | B6: 15% | C6: Current South African VAT rate.
A7: Managed Service Retainer | B7: R1,500/month excl. VAT | C7: Set by Gerhard (26 Sept 2026) - a lighter monthly retainer to keep the recurring bill low relative to Herotel and support the case for the build investment.
A8: Contract term - Vodacom Business Connect | B8: 36 months | C8: Confirmed 28 Sept 2026 against the CTTX Vodacom Reseller price book (Duane Forlee, Vodacom, 29 May 2026): the 36-month rate is slightly lower than 24-month. Monthly figure in this model is the confirmed 36-month client price at CTTX's standard 20% markup.
A10: Design Assumptions
A11: Single 9m mast carrying two 90-degree sector antennas (confirmed by Gerhard, 26 Sept 2026) - replaces the lodge's existing leaning gum-pole mount. This is NOT a two-site build; earlier drafts of this costing incorrectly read the field survey's two radio labels as two separate physical locations before this was corrected.
A12: Line-of-sight confirmed for all 28 subscriber links by Abel Ringisai's field RF survey (KML export, 22 Sept 2026).
A13: The longest links (1.7km-3.0km, to the staff village and Director's House) sit at the edge of the serving sector's range and still need a link-budget check to confirm they sustain full 100 Mbps symmetrical - flagged, not yet resolved.
A14: Cable run priced at an average 40m per run - to be confirmed once exact distances are measured on site.
A15: Vodacom Business Connect feasibility for this specific site has not yet been formally submitted/approved.
A17: What's Included in the 10-Year Support
A18: Years 1-3: monthly remote monitoring, quarterly on-site maintenance, 24/7 emergency support, proactive performance reporting, warranty-covered equipment troubleshooting/replacement.
A19: Years 4-10: ongoing remote monitoring, annual on-site maintenance/assessment, 24/7 support continuation, planned technology refresh, performance reporting.
A20: Throughout: no vendor lock-in on the owned hardware, scalability support, staff training and documentation.
A22: What's Excluded / Not Yet Priced
A23: Major component replacement (Lithium battery bank, inverter) near the end of the 10-year term - typical service life for this equipment is 8-10 years, so a replacement reserve may be needed in years 8-10 and is not included in the build cost above.
... A27: Any scope beyond the confirmed coverage zones (28 subscriber sites) without a signed change order.
