Workbook

Sheet 1. Inputs
A1: Barefoot Addo — Build Cost & Risk Model (INTERNAL)
A2: Yellow = input. Orange = TBC (my estimate until Abel/Gerhard confirms). Every other sheet reads from here. Ex VAT unless stated. 29 Sep 2026.
A4: A. Commercial
A5: VAT rate | B5: 0.15 | C5: SARS
A6: Target sell price to client (incl VAT) | B6: 335000 | C6: 29 Sep: client schedule generated at R335,000 (15.2% GP at current inputs). Change to test.
A7: Vodacom BC 100 Mbps 36m — CTTX cost / month | B7: 4152.04 | C7: Fixed Services AAG 092026 (Duane, 14 Sep 2026)
A8: Vodacom markup | B8: 0.2 | C8: Gerhard: 20% on this deal (policy recommends 25% for 100 Mbps)
A9: Vodacom 3rd-party site surcharge / month (cost) | B9: 0 | C9: AAG: '3rd-party infrastructure will incur additional cost'. Olifants Nek = Telkom site. Asked Duane 29 Sep.
A10: Vodacom installation (NRC) — cost | B10: 2607.83 | C10: AAG 092026
A11: CTTX managed-service retainer / month (client, ex VAT) | B11: 1500 | C11: Gerhard, 26 Sep
A12: Client's current monthly bill (incl VAT) | B12: 18105.6 | C12: Herotel invoice 8313058, 31 Aug 2026
A13: Client finance rate p.a. (if they apply for rent-to-own) | B13: 0.12 | C13: Gerhard's expectation, 29 Sep — client applies directly; CTTX is paid cash
A14: Finance term (months) | B14: 36
A16: B. Quantities (scenario switches)
A17: Base station radios (ePMP 4500L) | B17: 2 | C17: Abel BOM 29 Sep
A18: Sector antennas 90/120° | B18: 2 | C18: Abel BOM
A19: Subscriber radios — lodge/villa/spa/school/workshop cluster (excl. staff village) | B19: 15 | C19: Abel: 25 total, of which 10 are the staff village at 2.3–3 km
A20: Subscriber radios — staff village (10 houses) | B20: 10 | C20: SWITCH: set to 3 if Abel confirms clustering on LAN
A21: Staff-village LAN cable if clustered (metres, total) | B21: 0 | C21: SWITCH: only when staff radios < 10. Abel to give run lengths.
A22: Outdoor Wi-Fi 6 APs | B22: 4 | C22: SWITCH: Abel's BOM says 25; my challenge says ~4 (villa, main lodge, boma). Abel to confirm.
A23: Indoor Wi-Fi 6 ceiling APs | B23: 22 | C23: Total APs = 26 (Abel: 25 + 1). Indoor = 26 − outdoor.
A24: Managed 8-port PoE+ switches | B24: 2 | C24: Abel BOM
A25: Unmanaged 6-port PoE switches | B25: 2 | C25: Abel BOM
A26: 4U wall boxes | B26: 4 | C26: Abel BOM
A27: Mast height (enter 6 or 9) | B27: 6 | C27: SWITCH: Abel proposes 6m. 9m is the surveyed/safe height. Duane to confirm LOS at 6m.
A28: Outdoor cable per subscriber site (m) | B28: 40 | C28: Gerhard: average 40m per site (the 25 Sep quote wrongly carried 40m TOTAL)
... A31: Include extended warranties? (1 = yes, 0 = no) | B31: 0 | C31: Abel added 2-yr extensions; not priced on Duxnet V2. Recommend 0 (offer as option).
A33: C. Unit costs (ex VAT)
A34: ePMP 4500L 5GHz AP | B34: 8470 | C34: Duxnet DUX00455421 V2, 25 Sep — in stock
A35: ePMP sector antenna 90/120° | B35: 3209 | C35: Duxnet V2 — in stock
A36: ePMP Force 4525L SM 25dBi | B36: 2745 | C36: Duxnet V2 — Gerhard: in stock and secured (29 Sep)
A37: DuxNet Wi-Fi 6 ceiling AP | B37: 1025 | C37: Duxnet V2
A38: DuxNet outdoor Wi-Fi 6 AP | B38: 1885 | C38: Duxnet V2 — 84% more than indoor
A39: DuxNet 8-port PoE+ L2 cloud switch | B39: 1899 | C39: Duxnet V2
A40: Unmanaged 6-port PoE switch | B40: 650 | C40: TBC — Abel/Duxnet
A41: 4U wall box | B41: 600 | C41: TBC — Abel
A42: Ext. warranty 2 yrs — 4500L (each) | B42: 0 | C42: TBC — not on Duxnet V2
A43: Ext. warranty 2 yrs — 4525L (each) | B43: 0 | C43: TBC — not on Duxnet V2
A44: Solar kit: 2×660W Aiko, Victron MPPT 150/35, 5.32kWh LFP, Solis 5kW off-grid, DB components | B44: 25950.82 | C44: Herholdt's PLZ-Q488632, 29 Sep — valid 7 days, cash
A45: Outdoor cabinet, bare (CTTX stock) | B45: 8000 | C45: Gerhard, 29 Sep: floor R8,000 - confirmed
...

Sheet 2. Cost Build-up
A1: Cost build-up at the current scenario
A2: All formulas read from '1. Inputs'. Change a switch there and this recalculates.
A4: Line item | B4: Qty | C4: Unit cost | D4: Line cost | E4: TBC? | F4: Source / note
A5: 1. Backbone (mast, sectors, base radios)
A6: ePMP 4500L base station radio | B6: ='1. Inputs'!$B$17 | C6: ='1. Inputs'!$B$34 | D6: =B6*C6
A7: Sector antenna 90/120° | B7: ='1. Inputs'!$B$18 | C7: ='1. Inputs'!$B$35 | D7: =B7*C7
A8: Mast with plinth, installed (6m or 9m per switch) | B8: 1 | C8: =IF('1. Inputs'!$B$27=9,'1. Inputs'!$B$47,'1. Inputs'!$B$46) | D8: =B8*C8 | E8: TBC | F8: 6m cost is an estimate; LOS at 6m unconfirmed
A9: Ext. warranty — 4500L | B9: ='1. Inputs'!$B$31*'1. Inputs'!$B$17 | C9: ='1. Inputs'!$B$42 | D9: =B9*C9 | E9: TBC
A10: Backbone subtotal | D10: =SUM(D6:D9)
A12: 2. Distribution (subscriber radios to buildings)
A13: Force 4525L subscriber radio — main cluster | B13: ='1. Inputs'!$B$19 | C13: ='1. Inputs'!$B$36 | D13: =B13*C13
A14: Force 4525L subscriber radio — staff village | B14: ='1. Inputs'!$B$20 | C14: ='1. Inputs'!$B$36 | D14: =B14*C14 | E14: TBC | F14: 10 today; 3 if clustered on LAN
A15: Radio brackets | B15: ='1. Inputs'!$B$19+'1. Inputs'!$B$20 | C15: ='1. Inputs'!$B$48 | D15: =B15*C15
A16: Outdoor cable (per-site average × sites) | B16: =('1. Inputs'!$B$19+'1. Inputs'!$B$20)*'1. Inputs'!$B$28 | C16: ='1. Inputs'!$B$49 | D16: =B16*C16 | F16: R12/m is below rate card for armoured cable — see risk
A17: Staff-village LAN cable + trenching (only if clustered) | B17: ='1. Inputs'!$B$21 | C17: ='1. Inputs'!$B$50 | D17: =B17*C17 | E17: TBC
A18: Ext. warranty — 4525L | B18: ='1. Inputs'!$B$31*('1. Inputs'!$B$19+'1. Inputs'!$B$20) | C18: ='1. Inputs'!$B$43 | D18: =B18*C18 | E18: TBC
A19: Distribution subtotal | D19: =SUM(D13:D18)
A21: 3. Wi-Fi & switching
A22: Indoor Wi-Fi 6 ceiling AP | B22: ='1. Inputs'!$B$23 | C22: ='1. Inputs'!$B$37 | D22: =B22*C22
A23: Outdoor Wi-Fi 6 AP | B23: ='1. Inputs'!$B$22 | C23: ='1. Inputs'!$B$38 | D23: =B23*C23 | E23: TBC | F23: Abel's BOM has 25 outdoor; challenge says ~4
A24: Managed 8-port PoE+ switch | B24: ='1. Inputs'!$B$24 | C24: ='1. Inputs'!$B$39 | D24: =B24*C24
A25: Unmanaged 6-port PoE switch | B25: ='1. Inputs'!$B$25 | C25: ='1. Inputs'!$B$40 | D25: =B25*C25 | E25: TBC
A26: 4U wall box | B26: ='1. Inputs'!$B$26 | C26: ='1. Inputs'!$B$41 | D26: =B26*C26 | E26: TBC
A27: Wi-Fi & switching subtotal | D27: =SUM(D22:D26)
A29: 4. Power
A30: Solar kit (Herholdt's Q488632) | B30: 1 | C30: ='1. Inputs'!$B$44 | D30: =B30*C30 | F30: Quote valid to 6 Oct; cash terms
A31: Outdoor cabinet, bare | B31: 1 | C31: ='1. Inputs'!$B$45 | D31: =B31*C31 | E31: TBC
A32: Power subtotal | D32: =SUM(D30:D31)
A34: 5. Labour & travel
A35: Survey & design | B35: 1 | C35: ='1. Inputs'!$B$51 | D35: =B35*C35
A36: Installation — 2-technician team (days) | B36: ='1. Inputs'!$B$29 | C36: ='1. Inputs'!$B$52 | D36: =B36*C36
A37: Commissioning & testing | B37: 1 | C37: ='1. Inputs'!$B$53 | D37: =B37*C37
A38: Documentation & handover | B38: 1 | C38: ='1. Inputs'!$B$54 | D38: =B38*C38
A39: Overnight stays | B39: ='1. Inputs'!$B$30 | C39: ='1. Inputs'!$B$55 | D39: =B39*C39 | E39: TBC
A40: Labour & travel subtotal | D40: =SUM(D35:D39)
A42: TOTAL BUILD COST (ex VAT) | D42: =SUM(D10,D19,D27,D32,D40)
A43: of which TBC lines (estimates) | D43: =SUMIF(E5:E41,"TBC",D5:D41)
A45: Sell price to client (ex VAT) | D45: ='1. Inputs'!$B$6/(1+'1. Inputs'!$B$5)
A46: Sell price to client (incl VAT) | D46: ='1. Inputs'!$B$6
A47: GROSS PROFIT on the build (ex VAT) | D47: ='2. Cost Build-up'!$D$45-'2. Cost Build-up'!$D$42
...

Sheet 3. Risk Register
A1: What is our risk at this price? — every open item as rand exposure against the GP
A2: Probability = input (yellow). Exposure is calculated from the Inputs. Expected = probability × exposure. Worst case = everything hits at once.
A4: Risk | B4: Probability | C4: Exposure (ex VAT) | D4: Expected cost | E4: Mitigation / who closes it | F4: Status
A5: Mast: 6m has no usable LOS → build 9m. Gerhard stood at the mast position 29 Sep and saw clear LOS to Olifants Nek at ground level; Vodacom's own confirmation at 6m and Abel's 3 km staff-village LOS remain. | B5: 0.15 | C5: ='1. Inputs'!$B$47-IF('1. Inputs'!$B$27=9,'1. Inputs'!$B$47,'1. Inputs'!$B$46) | D5: =B5*C5 | E5: Vodacom desktop confirmation (Duane, asked 29 Sep); Abel: staff village LOS at 6m | F5: REDUCED
A6: 6m mast cost - CONFIRMED R22,000 (Gerhard 29 Sep) | B6: 0 | C6: =5000 | D6: =B6*C6 | E6: Gerhard prices from stock | F6: CLOSED
A7: Bare cabinet cost - CONFIRMED R8,000 (Gerhard 29 Sep) | B7: 0 | C7: =4000 | D7: =B7*C7 | E7: Gerhard prices from stock | F7: CLOSED
A8: Outdoor APs: Abel insists on 25 outdoor, not 4 | B8: 0.35 | C8: =(25-'1. Inputs'!$B$22)*('1. Inputs'!$B$38-'1. Inputs'!$B$37) | D8: =B8*C8 | E8: Abel confirms which buildings need outdoor units | F8: OPEN
A9: Staff-village clustering NOT feasible (stay at 10 radios) — only if the scenario assumes 3 | B9: 0.5 | C9: =IF('1. Inputs'!$B$20<10,(10-'1. Inputs'!$B$20)*('1. Inputs'!$B$36+'1. Inputs'!$B$48),0) | D9: =B9*C9 | E9: Abel: house spacing, trenching | F9: OPEN
A10: Cable: armoured grade required (R30/m vs R12/m) | B10: 0.4 | C10: =('1. Inputs'!$B$19+'1. Inputs'!$B$20)*'1. Inputs'!$B$28*(30-'1. Inputs'!$B$49) | D10: =B10*C10 | E10: Abel confirms grade at survey; rate card says R28–45/m | F10: OPEN
A11: Installation overruns by 1 day beyond the planned 4 | B11: 0.25 | C11: =1*'1. Inputs'!$B$52 | D11: =B11*C11 | E11: Plan 4 days; or accept as GP erosion | F11: REDUCED
A12: Overnight stays needed (3 nights, 2 techs) | B12: 0.4 | C12: =3*'1. Inputs'!$B$55 | D12: =B12*C12 | E12: Confirm with Abel; day trips are 3h30 round trip | F12: OPEN
A13: Extended warranties expected by client at no extra charge | B13: 0.2 | C13: =2*'1. Inputs'!$B$42+('1. Inputs'!$B$19+'1. Inputs'!$B$20)*'1. Inputs'!$B$43 | D13: =B13*C13 | E13: Price them; offer as option — currently R0 as TBC | F13: OPEN
A14: Unmanaged switches / wall boxes cost more than estimated | B14: 0.4 | C14: =1500 | D14: =B14*C14 | E14: Abel prices from Duxnet/Pinnacle | F14: OPEN
A15: Herholdt's quote lapses (7 days) and re-prices up 10% | B15: 0.3 | C15: =0.10*'1. Inputs'!$B$44 | D15: =B15*C15 | E15: Order on deposit receipt; or re-quote | F15: OPEN
A16: Duxnet price change on exchange rate before order (5%) | B16: 0.3 | C16: =0.05*('1. Inputs'!$B$17*'1. Inputs'!$B$34+'1. Inputs'!$B$18*'1. Inputs'!$B$35+('1. Inputs'!$B$19+'1. Inputs'!$B$20)*'1. Inputs'!$B$36+'1. Inputs'!$B$23*'1. Inputs'!$B$37+'1. Inputs'!$B$22*'1. Inputs'!$B$38+'1. Inputs'!$B$24*'1. Inputs'!$B$39) | D16: =B16*C16 | E16: Duxnet: 'prices valid only for in-stock items, subject to exchange rate'. Order promptly. | F16: OPEN
A17: Vodacom 3rd-party surcharge at Olifants Nek — CTTX absorbs it for the 36-month term rather than re-open the price | B17: 0.3 | C17: =36*500 | D17: =B17*C17 | E17: Asked Duane 29 Sep. If confirmed before quoting, it goes into the MRC, not our margin. | F17: OPEN
A18: Vodacom feasibility FAILS after build — client keeps current link; retainer only (lost Vodacom margin over 36m) | B18: 0.15 | C18: =36*'1. Inputs'!$B$7*'1. Inputs'!$B$8 | D18: =B18*C18 | E18: Make the order conditional on desktop feasibility; the build still stands on its own | F18: OPEN
A20: Expected risk cost (sum of probability × exposure) | D20: =SUM(D5:D18)
A21: Worst case (every risk hits) | D21: =SUM(C5:C18)
A23: GP at the target price (from sheet 2) | D23: ='2. Cost Build-up'!$D$47
A24: GP after EXPECTED risk | D24: ='2. Cost Build-up'!$D$47-'3. Risk Register'!$D$20
A25: GP in the WORST case | D25: ='2. Cost Build-up'!$D$47-'3. Risk Register'!$D$21
A27: How to read this: if 'GP after expected risk' is still positive and acceptable, R305k is a price we can stand behind once the TBC lines are confirmed. If 'worst case' is negative, that is the amount we must protect with conditions (feasibility first, deposit before order, 4-day install in the labour line) or with a higher price.

Sheet 4. Client ROI
A1: Client view at this price — outright vs their own finance
A2: Incl VAT. Current bill from Herotel invoice. CTTX monthly locked 36 months, then 8%; current provider +8%/yr from year 2 (assumption).
A4: Vodacom BC 100 Mbps client MRC (incl VAT) | B4: =('1. Inputs'!$B$7+'1. Inputs'!$B$9)*(1+'1. Inputs'!$B$8)*(1+'1. Inputs'!$B$5)
A5: CTTX retainer (incl VAT) | B5: ='1. Inputs'!$B$11*(1+'1. Inputs'!$B$5)
A6: New monthly bill (incl VAT) | B6: =B4+B5
A7: Saving per month vs today | B7: ='1. Inputs'!$B$12-B6
A8: Upfront: build + Vodacom NRC (incl VAT) | B8: ='1. Inputs'!$B$6+'1. Inputs'!$B$10*(1+'1. Inputs'!$B$8)*(1+'1. Inputs'!$B$5)
A9: Simple payback (months) | B9: =B8/B7
A11: Year-by-year (cumulative, incl VAT)
B12: Year 0 | C12: Year 1 | D12: Year 2 | E12: Year 3 | F12: Year 4 | G12: Year 5
A13: Current provider cumulative | B13: 0 | C13: =B13+'1. Inputs'!$B$12*12*1.08^0 | D13: =C13+'1. Inputs'!$B$12*12*1.08^1 | E13: =D13+'1. Inputs'!$B$12*12*1.08^2 | F13: =E13+'1. Inputs'!$B$12*12*1.08^3 | G13: =F13+'1. Inputs'!$B$12*12*1.08^4
A14: CTTX path cumulative (upfront at year 0) | B14: ='4. Client ROI'!$B$8 | C14: =B14+'4. Client ROI'!$B$6*12*1 | D14: =C14+'4. Client ROI'!$B$6*12*1 | E14: =D14+'4. Client ROI'!$B$6*12*1 | F14: =E14+'4. Client ROI'!$B$6*12*1.08^1 | G14: =F14+'4. Client ROI'!$B$6*12*1.08^2
A15: Cumulative saving (current − CTTX) | B15: =B13-B14 | C15: =C13-C14 | D15: =D13-D14 | E15: =E13-E14 | F15: =F13-F14 | G15: =G13-G14
A17: 36-month net (end of agreement) | B17: =E15
A18: 5-year net | B18: =G15
A20: If the client finances the build themselves (they apply directly; CTTX is paid cash)
A21: Finance rate p.a. | B21: ='1. Inputs'!$B$13
A22: Term (months) | B22: ='1. Inputs'!$B$14
A23: Monthly instalment on the build (incl VAT) | B23: =PMT('1. Inputs'!$B$13/12,'1. Inputs'!$B$14,-'1. Inputs'!$B$6)
A24: Total monthly during the term (instalment + connectivity + retainer) | B24: =B23+'4. Client ROI'!$B$6
A25: Versus today's bill (negative = cheaper than now) | B25: =B24-'1. Inputs'!$B$12
A26: Total finance cost over the term | B26: =B23*'1. Inputs'!$B$14-'1. Inputs'!$B$6
A27: Monthly after the term (network owned) | B27: ='4. Client ROI'!$B$6

Sheet 5. Scenarios
A1: Price × scenario — GP on the build (snapshot values, ex VAT; live model is sheets 1–3)
A2: Cost scenarios: (a) Abel's BOM as sent (25 outdoor APs, 10 staff radios, 40m cable total, my TBC estimates); (b) model defaults (4 outdoor APs, 10 staff radios, 40m cable per site, TBC estimates); (c) all levers land (3 staff radios + 300m LAN, 6m mast R20k, bare cabinet R6k, 4 outdoor APs).
A4: Cost scenario → GP (GP%) | B4: Sell R305,000 incl | C4: Sell R325,000 incl | D4: Sell R345,000 incl | E4: Sell R355,000 incl
A5: (a) Abel BOM as sent cost R258,562 | B5: R6,655 (2.5%) | C5: R24,047 (8.5%) | D5: R41,438 (13.8%) | E5: R50,134 (16.2%)
A6: (b) Model defaults cost R252,022 | B6: R13,196 (5.0%) | C6: R30,587 (10.8%) | D6: R47,978 (16.0%) | E6: R56,674 (18.4%)
A7: (c) All levers land cost R221,797 | B7: R43,421 (16.4%) | C7: R60,812 (21.5%) | D7: R78,203 (26.1%) | E7: R86,899 (28.2%)
A9: Price that holds 14.5% GP:
A10: (a) Abel BOM as sent | B10: R347,773 incl VAT
A11: (b) Model defaults | B11: R338,977 incl VAT
A12: (c) All levers land | B12: R298,323 incl VAT
A14: Reading: R305k only holds our margin if scenario (c) lands — staff-village clustering AND stock-priced mast/cabinet. At the model defaults, R345k is the price that keeps 14.5%; R305k leaves R13k before risk and goes negative after expected risk (sheet 3).
